Hi,<br>
<br>
There's been an error in the DAG <b>{{ti.dag_id}}</b> for <b>{{ti.task_id}}</b> task while execution on <b>{{ti.execution_date}}</b>.<br>
<br>
Exception:<br>{{exception_html}}<br>
<br>
View Logs: <b><a href="{{ti.log_url}}">Error log link</a></b><br>
<br>
Thanks and Regards,<br>
<b>Airflow Bot</b><br>
